Workbook

Sheet ORIGINAL ANNUAL BUDGET 
A1: Month | B1: Transactions (m) | C1: Avg Fee (₦) | D1: Revenue | E1: Marketing | F1: Operation | G1: Tech | H1: Staff | I1: Total Cost | J1: Profit
A2: Jan | B2: 2000000 | C2: 50 | D2: 100000000 | E2: 20000000 | F2: 15000000 | G2: 10000000 | H2: 18000000 | I2: 63000000 | J2: 37000000
A3: Feb | B3: 2100000 | C3: 50 | D3: 105000000 | E3: 20000000 | F3: 15000000 | G3: 10000000 | H3: 18000000 | I3: 63000000 | J3: 42000000
A4: Mar | B4: 2300000 | C4: 50 | D4: 115000000 | E4: 22000000 | F4: 16000000 | G4: 10000000 | H4: 18000000 | I4: 66000000 | J4: 49000000
A5: Apr | B5: 2400000 | C5: 50 | D5: 120000000 | E5: 22000000 | F5: 16000000 | G5: 11000000 | H5: 18000000 | I5: 67000000 | J5: 53000000
A6: May | B6: 2600000 | C6: 50 | D6: 130000000 | E6: 24000000 | F6: 17000000 | G6: 11000000 | H6: 19000000 | I6: 71000000 | J6: 59000000
A7: Jun | B7: 2800000 | C7: 50 | D7: 140000000 | E7: 25000000 | F7: 18000000 | G7: 12000000 | H7: 19000000 | I7: 74000000 | J7: 66000000
A8: Jul | B8: 3000000 | C8: 50 | D8: 150000000 | E8: 26000000 | F8: 18000000 | G8: 12000000 | H8: 20000000 | I8: 76000000 | J8: 74000000
A9: Aug | B9: 3100000 | C9: 50 | D9: 155000000 | E9: 26000000 | F9: 19000000 | G9: 12000000 | H9: 20000000 | I9: 77000000 | J9: 78000000
A10: Sep | B10: 3200000 | C10: 50 | D10: 160000000 | E10: 27000000 | F10: 19000000 | G10: 13000000 | H10: 20000000 | I10: 79000000 | J10: 81000000
A11: Oct | B11: 3400000 | C11: 50 | D11: 170000000 | E11: 28000000 | F11: 20000000 | G11: 13000000 | H11: 21000000 | I11: 82000000 | J11: 88000000
A12: Nov | B12: 3600000 | C12: 50 | D12: 180000000 | E12: 29000000 | F12: 21000000 | G12: 14000000 | H12: 21000000 | I12: 85000000 | J12: 95000000
A13: Dec | B13: 3800000 | C13: 50 | D13: 190000000 | E13: 30000000 | F13: 22000000 | G13: 15000000 | H13: 22000000 | I13: 89000000 | J13: 101000000

Sheet ACTUAL RESULTS (JUL–DEC)
A1: Month | B1: Transactions (m) | C1: Avg Fee (₦) | D1: Actual Revenue | E1: Actual Cost
A2: Jul | B2: 1800000 | C2: 48 | D2: 86400000 | E2: 66000000
A3: Aug | B3: 1900000 | C3: 48 | D3: 91200000 | E3: 65000000
A4: Sep | B4: 2000000 | C4: 49 | D4: 98000000 | E4: 68000000
A5: Oct | B5: 2100000 | C5: 49 | D5: 102900000 | E5: 70000000
A6: Nov | B6: 2200000 | C6: 49 | D6: 107800000 | E6: 72000000
A7: Dec | B7: 2400000 | C7: 49 | D7: 117600000 | E7: 74000000

Sheet FORECAST
B2: Scenario 1
B3: Transactions Grow MoM(%) | C3: 0.08
B4: Average Fee Remains ₦ | C4: 49
B5: Costs Grow MoM(%) | C5: 0.05
B7: Scenario 2
B8: Transactions Grow MoM(%) | C8: 0.12
B9: Average Fee Remains ₦ | C9: 52
B10: Costs Grow MoM(%) | C10: 0.1
B12: Scenario 3
B13: Transactions Grow MoM(%) | C13: 0.04
B14: Average Fee Remains ₦ | C14: 47
B15: Costs Grow MoM(%) | C15: 0.1
B20: Live Case | C20: Actual | I20: Forecast
B21: =B28 -> Month | C21: 45863 | D21: 45894 | E21: 45925 | F21: 45955 | G21: 45986 | H21: 46016 | I21: 46047 | J21: 46078 | K21: 46106 | L21: 46137 | M21: 46167 | N21: 46198 | O21: 46228 | P21: 46259 | Q21: 46290 | R21: 46320 | S21: 46351 | T21: 46381
B22: =B29 -> Transactions (m) | C22: =C29 -> 1800000 | D22: =D29 -> 1900000 | E22: =E29 -> 2000000 | F22: =F29 -> 2100000 | G22: =G29 -> 2200000 | H22: =H29 -> 2400000 | I22: =CHOOSE('INCOME STATEMENT'!$C$3,FORECAST!I36,FORECAST!I43,FORECAST!I50) -> 2592000 | J22: =CHOOSE('INCOME STATEMENT'!$C$3,FORECAST!J36,FORECAST!J43,FORECAST!J50) -> 2799360 | K22: =CHOOSE('INCOME STATEMENT'!$C$3,FORECAST!K36,FORECAST!K43,FORECAST!K50) -> 3023308.8 | L22: =CHOOSE('INCOME STATEMENT'!$C$3,FORECAST!L36,FORECAST!L43,FORECAST!L50) -> 3265173.5 | M22: =CHOOSE('INCOME STATEMENT'!$C$3,FORECAST!M36,FORECAST!M43,FORECAST!M50) -> 3526387.4 | N22: =CHOOSE('INCOME STATEMENT'!$C$3,FORECAST!N36,FORECAST!N43,FORECAST!N50) -> 3808498.4 | O22: =CHOOSE('INCOME STATEMENT'!$C$3,FORECAST!O36,FORECAST!O43,FORECAST!O50) -> 4113178.2 | P22: =CHOOSE('INCOME STATEMENT'!$C$3,FORECAST!P36,FORECAST!P43,FORECAST!P50) -> 4442232.5 | ... T22: =CHOOSE('INCOME STATEMENT'!$C$3,FORECAST!T36,FORECAST!T43,FORECAST!T50) -> 6043608.3
B23: =B30 -> Avg Fee (₦) | C23: =C30 -> 48 | D23: =D30 -> 48 | E23: =E30 -> 49 | F23: =F30 -> 49 | G23: =G30 -> 49 | H23: =H30 -> 49 | I23: =CHOOSE('INCOME STATEMENT'!$C$3,FORECAST!I37,FORECAST!I44,FORECAST!I51) -> 49 | J23: =CHOOSE('INCOME STATEMENT'!$C$3,FORECAST!J37,FORECAST!J44,FORECAST!J51) -> 49 | K23: =CHOOSE('INCOME STATEMENT'!$C$3,FORECAST!K37,FORECAST!K44,FORECAST!K51) -> 49 | L23: =CHOOSE('INCOME STATEMENT'!$C$3,FORECAST!L37,FORECAST!L44,FORECAST!L51) -> 49 | M23: =CHOOSE('INCOME STATEMENT'!$C$3,FORECAST!M37,FORECAST!M44,FORECAST!M51) -> 49 | N23: =CHOOSE('INCOME STATEMENT'!$C$3,FORECAST!N37,FORECAST!N44,FORECAST!N51) -> 49 | O23: =CHOOSE('INCOME STATEMENT'!$C$3,FORECAST!O37,FORECAST!O44,FORECAST!O51) -> 49 | P23: =CHOOSE('INCOME STATEMENT'!$C$3,FORECAST!P37,FORECAST!P44,FORECAST!P51) -> 49 | ... T23: =CHOOSE('INCOME STATEMENT'!$C$3,FORECAST!T37,FORECAST!T44,FORECAST!T51) -> 49
B24: =B31 -> Actual Revenue | C24: =C31 -> 86400000 | D24: =D31 -> 91200000 | E24: =E31 -> 98000000 | F24: =F31 -> 102900000 | G24: =G31 -> 107800000 | H24: =H31 -> 117600000 | I24: =CHOOSE('INCOME STATEMENT'!$C$3,FORECAST!I38,FORECAST!I45,FORECAST!I52) -> 127008000 | J24: =CHOOSE('INCOME STATEMENT'!$C$3,FORECAST!J38,FORECAST!J45,FORECAST!J52) -> 137168640 | K24: =CHOOSE('INCOME STATEMENT'!$C$3,FORECAST!K38,FORECAST!K45,FORECAST!K52) -> 1.4814213e+08 | L24: =CHOOSE('INCOME STATEMENT'!$C$3,FORECAST!L38,FORECAST!L45,FORECAST!L52) -> 1.599935e+08 | M24: =CHOOSE('INCOME STATEMENT'!$C$3,FORECAST!M38,FORECAST!M45,FORECAST!M52) -> 1.7279298e+08 | N24: =CHOOSE('INCOME STATEMENT'!$C$3,FORECAST!N38,FORECAST!N45,FORECAST!N52) -> 1.8661642e+08 | O24: =CHOOSE('INCOME STATEMENT'!$C$3,FORECAST!O38,FORECAST!O45,FORECAST!O52) -> 2.0154573e+08 | P24: =CHOOSE('INCOME STATEMENT'!$C$3,FORECAST!P38,FORECAST!P45,FORECAST!P52) -> 2.1766939e+08 | ... T24: =CHOOSE('INCOME STATEMENT'!$C$3,FORECAST!T38,FORECAST!T45,FORECAST!T52) -> 2.9613681e+08
B25: =B32 -> Actual Cost | C25: =C32 -> 66000000 | D25: =D32 -> 65000000 | E25: =E32 -> 68000000 | F25: =F32 -> 70000000 | G25: =G32 -> 72000000 | H25: =H32 -> 74000000 | I25: =CHOOSE('INCOME STATEMENT'!$C$3,FORECAST!I39,FORECAST!I46,FORECAST!I53) -> 77700000 | J25: =CHOOSE('INCOME STATEMENT'!$C$3,FORECAST!J39,FORECAST!J46,FORECAST!J53) -> 81585000 | K25: =CHOOSE('INCOME STATEMENT'!$C$3,FORECAST!K39,FORECAST!K46,FORECAST!K53) -> 85664250 | L25: =CHOOSE('INCOME STATEMENT'!$C$3,FORECAST!L39,FORECAST!L46,FORECAST!L53) -> 89947462 | M25: =CHOOSE('INCOME STATEMENT'!$C$3,FORECAST!M39,FORECAST!M46,FORECAST!M53) -> 94444836 | N25: =CHOOSE('INCOME STATEMENT'!$C$3,FORECAST!N39,FORECAST!N46,FORECAST!N53) -> 99167077 | O25: =CHOOSE('INCOME STATEMENT'!$C$3,FORECAST!O39,FORECAST!O46,FORECAST!O53) -> 1.0412543e+08 | P25: =CHOOSE('INCOME STATEMENT'!$C$3,FORECAST!P39,FORECAST!P46,FORECAST!P53) -> 1.093317e+08 | ... T25: =CHOOSE('INCOME STATEMENT'!$C$3,FORECAST!T39,FORECAST!T46,FORECAST!T53) -> 1.3289337e+08
B27: Base Case | C27: Actual | I27: Forecast
B28: ='ACTUAL RESULTS (JUL–DEC)'!A1 -> Month | C28: 45863 | D28: 45894 | E28: 45925 | F28: 45955 | G28: 45986 | H28: 46016 | I28: 46047 | J28: 46078 | K28: 46106 | L28: 46137 | M28: 46167 | N28: 46198 | O28: 46228 | P28: 46259 | Q28: 46290 | R28: 46320 | S28: 46351 | T28: 46381
B29: ='ACTUAL RESULTS (JUL–DEC)'!B1 -> Transactions (m) | C29: {=TRANSPOSE('ACTUAL RESULTS (JUL–DEC)'!B2:B7)} -> 1800000 | D29: 1900000 | E29: 2000000 | F29: 2100000 | G29: 2200000 | H29: 2400000 | I29: =_xlfn.FORECAST.ETS(I$28,$C29:H29,$C$28:H$28) -> 2478440.5 | J29: =_xlfn.FORECAST.ETS(J$28,$C29:I29,$C$28:I$28) -> 2592012.3 | K29: =_xlfn.FORECAST.ETS(K$28,$C29:J29,$C$28:J$28) -> 2708778.9 | L29: =_xlfn.FORECAST.ETS(L$28,$C29:K29,$C$28:K$28) -> 2825438.5 | M29: =_xlfn.FORECAST.ETS(M$28,$C29:L29,$C$28:L$28) -> 2942028.5 | N29: =_xlfn.FORECAST.ETS(N$28,$C29:M29,$C$28:M$28) -> 3058573.1 | O29: =_xlfn.FORECAST.ETS(O$28,$C29:N29,$C$28:N$28) -> 3175087.5 | P29: =_xlfn.FORECAST.ETS(P$28,$C29:O29,$C$28:O$28) -> 3291581.4 | ... T29: =_xlfn.FORECAST.ETS(T$28,$C29:S29,$C$28:S$28) -> 3757441.9
B30: ='ACTUAL RESULTS (JUL–DEC)'!C1 -> Avg Fee (₦) | C30: {=TRANSPOSE('ACTUAL RESULTS (JUL–DEC)'!C2:C7)} -> 48 | D30: 48 | E30: 49 | F30: 49 | G30: 49 | H30: 49 | I30: =_xlfn.FORECAST.ETS(I$28,$C30:H30,$C$28:H$28) -> 49.313991 | J30: =_xlfn.FORECAST.ETS(J$28,$C30:I30,$C$28:I$28) -> 49.55052 | K30: =_xlfn.FORECAST.ETS(K$28,$C30:J30,$C$28:J$28) -> 49.736373 | L30: =_xlfn.FORECAST.ETS(L$28,$C30:K30,$C$28:K$28) -> 49.933329 | M30: =_xlfn.FORECAST.ETS(M$28,$C30:L30,$C$28:L$28) -> 50.124899 | N30: =_xlfn.FORECAST.ETS(N$28,$C30:M30,$C$28:M$28) -> 50.31718 | O30: =_xlfn.FORECAST.ETS(O$28,$C30:N30,$C$28:N$28) -> 50.526298 | P30: =_xlfn.FORECAST.ETS(P$28,$C30:O30,$C$28:O$28) -> 50.723862 | ... T30: =_xlfn.FORECAST.ETS(T$28,$C30:S30,$C$28:S$28) -> 51.515002
B31: ='ACTUAL RESULTS (JUL–DEC)'!D1 -> Actual Revenue | C31: {=TRANSPOSE('ACTUAL RESULTS (JUL–DEC)'!D2:D7)} -> 86400000 | D31: 91200000 | E31: 98000000 | F31: 102900000 | G31: 107800000 | H31: 117600000 | I31: =I29*I30 -> 1.2222179e+08 | J31: =J29*J30 -> 1.2843556e+08 | K31: =K29*K30 -> 1.3472484e+08 | L31: =L29*L30 -> 1.4108355e+08 | M31: =M29*M30 -> 1.4746888e+08 | N31: =N29*N30 -> 1.5389877e+08 | O31: =O29*O30 -> 1.6042542e+08 | P31: =P29*P30 -> 1.6696172e+08 | ... T31: =T29*T30 -> 1.9356463e+08
B32: ='ACTUAL RESULTS (JUL–DEC)'!E1 -> Actual Cost | C32: {=TRANSPOSE('ACTUAL RESULTS (JUL–DEC)'!E2:E7)} -> 66000000 | D32: 65000000 | E32: 68000000 | F32: 70000000 | G32: 72000000 | H32: 74000000 | I32: =_xlfn.FORECAST.ETS(I$28,$C32:H32,$C$28:H$28) -> 75919749 | J32: =_xlfn.FORECAST.ETS(J$28,$C32:I32,$C$28:I$28) -> 77669695 | K32: =_xlfn.FORECAST.ETS(K$28,$C32:J32,$C$28:J$28) -> 79539420 | L32: =_xlfn.FORECAST.ETS(L$28,$C32:K32,$C$28:K$28) -> 81409584 | M32: =_xlfn.FORECAST.ETS(M$28,$C32:L32,$C$28:L$28) -> 83280218 | N32: =_xlfn.FORECAST.ETS(N$28,$C32:M32,$C$28:M$28) -> 85151189 | O32: =_xlfn.FORECAST.ETS(O$28,$C32:N32,$C$28:N$28) -> 87022358 | P32: =_xlfn.FORECAST.ETS(P$28,$C32:O32,$C$28:O$28) -> 88893616 | ... T32: =_xlfn.FORECAST.ETS(T$28,$C32:S32,$C$28:S$28) -> 96378304
B34: Scenario 1 | C34: Actual | I34: Forecast
B35: =B28 -> Month | C35: =C28 -> 45863 | D35: =D28 -> 45894 | E35: =E28 -> 45925 | F35: =F28 -> 45955 | G35: =G28 -> 45986 | H35: =H28 -> 46016 | I35: =I28 -> 46047 | ... T35: =T28 -> 46381
B36: =B29 -> Transactions (m) | C36: =C29 -> 1800000 | D36: =D29 -> 1900000 | E36: =E29 -> 2000000 | F36: =F29 -> 2100000 | G36: =G29 -> 2200000 | H36: =H29 -> 2400000 | I36: =H36*(1+$C$3) -> 2592000 | J36: =I36*(1+$C$3) -> 2799360 | K36: =J36*(1+$C$3) -> 3023308.8 | L36: =K36*(1+$C$3) -> 3265173.5 | M36: =L36*(1+$C$3) -> 3526387.4 | N36: =M36*(1+$C$3) -> 3808498.4 | O36: =N36*(1+$C$3) -> 4113178.2 | P36: =O36*(1+$C$3) -> 4442232.5 | ... T36: =S36*(1+$C$3) -> 6043608.3
B37: =B30 -> Avg Fee (₦) | C37: =C30 -> 48 | D37: =D30 -> 48 | E37: =E30 -> 49 | F37: =F30 -> 49 | G37: =G30 -> 49 | H37: =H30 -> 49 | I37: =$C$4 -> 49 | J37: =$C$4 -> 49 | K37: =$C$4 -> 49 | L37: =$C$4 -> 49 | M37: =$C$4 -> 49 | N37: =$C$4 -> 49 | O37: =$C$4 -> 49 | P37: =$C$4 -> 49 | ... T37: =$C$4 -> 49
B38: =B31 -> Actual Revenue | C38: =C31 -> 86400000 | D38: =D31 -> 91200000 | E38: =E31 -> 98000000 | F38: =F31 -> 102900000 | G38: =G31 -> 107800000 | H38: =H31 -> 117600000 | I38: =I36*I37 -> 127008000 | J38: =J36*J37 -> 137168640 | K38: =K36*K37 -> 1.4814213e+08 | L38: =L36*L37 -> 1.599935e+08 | M38: =M36*M37 -> 1.7279298e+08 | N38: =N36*N37 -> 1.8661642e+08 | O38: =O36*O37 -> 2.0154573e+08 | P38: =P36*P37 -> 2.1766939e+08 | ... T38: =T36*T37 -> 2.9613681e+08
B39: =B32 -> Actual Cost | C39: =C32 -> 66000000 | D39: =D32 -> 65000000 | E39: =E32 -> 68000000 | F39: =F32 -> 70000000 | G39: =G32 -> 72000000 | H39: =H32 -> 74000000 | I39: =H39*(1+$C$5) -> 77700000 | J39: =I39*(1+$C$5) -> 81585000 | K39: =J39*(1+$C$5) -> 85664250 | L39: =K39*(1+$C$5) -> 89947462 | M39: =L39*(1+$C$5) -> 94444836 | N39: =M39*(1+$C$5) -> 99167077 | O39: =N39*(1+$C$5) -> 1.0412543e+08 | P39: =O39*(1+$C$5) -> 1.093317e+08 | ... T39: =S39*(1+$C$5) -> 1.3289337e+08
B41: Scenario 2 | C41: Actual | I41: Forecast
B42: =B35 -> Month | C42: =C28 -> 45863 | D42: =D28 -> 45894 | E42: =E28 -> 45925 | F42: =F28 -> 45955 | G42: =G28 -> 45986 | H42: =H28 -> 46016 | I42: =I28 -> 46047 | J42: =J28 -> 46078 | ... T42: =T28 -> 46381
B43: =B36 -> Transactions (m) | C43: =C29 -> 1800000 | D43: =D29 -> 1900000 | E43: =E29 -> 2000000 | F43: =F29 -> 2100000 | G43: =G29 -> 2200000 | H43: =H29 -> 2400000 | I43: =H43*(1+$C$8) -> 2688000 | J43: =I43*(1+$C$8) -> 3010560 | K43: =J43*(1+$C$8) -> 3371827.2 | L43: =K43*(1+$C$8) -> 3776446.5 | M43: =L43*(1+$C$8) -> 4229620 | N43: =M43*(1+$C$8) -> 4737174.4 | O43: =N43*(1+$C$8) -> 5305635.4 | P43: =O43*(1+$C$8) -> 5942311.6 | ... T43: =S43*(1+$C$8) -> 9350342.4
B44: =B37 -> Avg Fee (₦) | C44: =C30 -> 48 | D44: =D30 -> 48 | E44: =E30 -> 49 | F44: =F30 -> 49 | G44: =G30 -> 49 | H44: =H30 -> 49 | I44: =$C$9 -> 52 | J44: =$C$9 -> 52 | K44: =$C$9 -> 52 | L44: =$C$9 -> 52 | M44: =$C$9 -> 52 | N44: =$C$9 -> 52 | O44: =$C$9 -> 52 | P44: =$C$9 -> 52 | ... T44: =$C$9 -> 52
B45: =B38 -> Actual Revenue | C45: =C31 -> 86400000 | D45: =D31 -> 91200000 | E45: =E31 -> 98000000 | F45: =F31 -> 102900000 | G45: =G31 -> 107800000 | H45: =H31 -> 117600000 | I45: =I43*I44 -> 1.39776e+08 | J45: =J43*J44 -> 1.5654912e+08 | K45: =K43*K44 -> 1.7533501e+08 | L45: =L43*L44 -> 1.9637522e+08 | M45: =M43*M44 -> 2.1994024e+08 | N45: =N43*N44 -> 2.4633307e+08 | O45: =O43*O44 -> 2.7589304e+08 | P45: =P43*P44 -> 3.090002e+08 | ... T45: =T43*T44 -> 4.862178e+08
B46: =B39 -> Actual Cost | C46: =C32 -> 66000000 | D46: =D32 -> 65000000 | E46: =E32 -> 68000000 | F46: =F32 -> 70000000 | G46: =G32 -> 72000000 | H46: =H32 -> 74000000 | I46: =H46*(1+$C$10) -> 81400000 | J46: =I46*(1+$C$10) -> 89540000 | K46: =J46*(1+$C$10) -> 98494000 | L46: =K46*(1+$C$10) -> 1.083434e+08 | M46: =L46*(1+$C$10) -> 1.1917774e+08 | N46: =M46*(1+$C$10) -> 1.3109551e+08 | O46: =N46*(1+$C$10) -> 1.4420507e+08 | P46: =O46*(1+$C$10) -> 1.5862557e+08 | ... T46: =S46*(1+$C$10) -> 2.322437e+08
B48: Scenario 3 | C48: Actual | I48: Forecast
B49: =B28 -> Month | C49: =C28 -> 45863 | D49: =D28 -> 45894 | E49: =E28 -> 45925 | F49: =F28 -> 45955 | G49: =G28 -> 45986 | H49: =H28 -> 46016 | I49: =I28 -> 46047 | ... T49: =T28 -> 46381
B50: =B29 -> Transactions (m) | C50: =C29 -> 1800000 | D50: =D29 -> 1900000 | E50: =E29 -> 2000000 | F50: =F29 -> 2100000 | G50: =G29 -> 2200000 | H50: =H29 -> 2400000 | I50: =H50*(1+$C$13) -> 2496000 | J50: =I50*(1+$C$13) -> 2595840 | K50: =J50*(1+$C$13) -> 2699673.6 | L50: =K50*(1+$C$13) -> 2807660.5 | M50: =L50*(1+$C$13) -> 2919967 | N50: =M50*(1+$C$13) -> 3036765.6 | O50: =N50*(1+$C$13) -> 3158236.3 | P50: =O50*(1+$C$13) -> 3284565.7 | ... T50: =S50*(1+$C$13) -> 3842477.3
B51: =B30 -> Avg Fee (₦) | C51: =C30 -> 48 | D51: =D30 -> 48 | E51: =E30 -> 49 | F51: =F30 -> 49 | G51: =G30 -> 49 | H51: =H30 -> 49 | I51: =$C$14 -> 47 | J51: =$C$14 -> 47 | K51: =$C$14 -> 47 | L51: =$C$14 -> 47 | M51: =$C$14 -> 47 | N51: =$C$14 -> 47 | O51: =$C$14 -> 47 | P51: =$C$14 -> 47 | ... T51: =$C$14 -> 47
...

Sheet INCOME STATEMENT
B3: Operating Expensive Scenario | C3: 1
B4: Revenue | C4: =SUM(FORECAST!I24:T24) -> 2.4102469e+09
B8: Income Statement Forecast
B9: Month | C9: =FORECAST!I21 -> 46047 | D9: =FORECAST!J21 -> 46078 | E9: =FORECAST!K21 -> 46106 | F9: =FORECAST!L21 -> 46137 | G9: =FORECAST!M21 -> 46167 | H9: =FORECAST!N21 -> 46198 | I9: =FORECAST!O21 -> 46228 | J9: =FORECAST!P21 -> 46259 | ... N9: =FORECAST!T21 -> 46381
B10: Revenue | C10: =FORECAST!I24 -> 127008000 | D10: =FORECAST!J24 -> 137168640 | E10: =FORECAST!K24 -> 1.4814213e+08 | F10: =FORECAST!L24 -> 1.599935e+08 | G10: =FORECAST!M24 -> 1.7279298e+08 | H10: =FORECAST!N24 -> 1.8661642e+08 | I10: =FORECAST!O24 -> 2.0154573e+08 | J10: =FORECAST!P24 -> 2.1766939e+08 | ... N10: =FORECAST!T24 -> 2.9613681e+08
B11: Actual Cost | C11: =FORECAST!I25 -> 77700000 | D11: =FORECAST!J25 -> 81585000 | E11: =FORECAST!K25 -> 85664250 | F11: =FORECAST!L25 -> 89947462 | G11: =FORECAST!M25 -> 94444836 | H11: =FORECAST!N25 -> 99167077 | I11: =FORECAST!O25 -> 1.0412543e+08 | J11: =FORECAST!P25 -> 1.093317e+08 | ... N11: =FORECAST!T25 -> 1.3289337e+08
B12: Gross Profit | C12: =C10-C11 -> 49308000 | D12: =D10-D11 -> 55583640 | E12: =E10-E11 -> 62477881 | F12: =F10-F11 -> 70046039 | G12: =G10-G11 -> 78348146 | H12: =H10-H11 -> 87449343 | I12: =I10-I11 -> 97420303 | J12: =J10-J11 -> 1.0833769e+08 | ... N12: =N10-N11 -> 1.6324344e+08
B15: Operationg Expenses | C15: =C9 -> 46047 | D15: =D9 -> 46078 | E15: =E9 -> 46106 | F15: =F9 -> 46137 | G15: =G9 -> 46167 | H15: =H9 -> 46198 | I15: =I9 -> 46228 | J15: =J9 -> 46259 | ... N15: =N9 -> 46381
B16: {=TRANSPOSE('ORIGINAL ANNUAL BUDGET '!E1:H1)} -> Marketing | C16: {=TRANSPOSE('ORIGINAL ANNUAL BUDGET '!E2:E13)} -> 20000000 | D16: 20000000 | E16: 22000000 | F16: 22000000 | G16: 24000000 | H16: 25000000 | I16: 26000000 | J16: 26000000 | K16: 27000000 | L16: 28000000 | M16: 29000000 | N16: 30000000
B17: Operation | C17: {=TRANSPOSE('ORIGINAL ANNUAL BUDGET '!F2:F13)} -> 15000000 | D17: 15000000 | E17: 16000000 | F17: 16000000 | G17: 17000000 | H17: 18000000 | I17: 18000000 | J17: 19000000 | K17: 19000000 | L17: 20000000 | M17: 21000000 | N17: 22000000
B18: Tech | C18: {=TRANSPOSE('ORIGINAL ANNUAL BUDGET '!G2:G13)} -> 10000000 | D18: 10000000 | E18: 10000000 | F18: 11000000 | G18: 11000000 | H18: 12000000 | I18: 12000000 | J18: 12000000 | K18: 13000000 | L18: 13000000 | M18: 14000000 | N18: 15000000
B19: Staff | C19: {=TRANSPOSE('ORIGINAL ANNUAL BUDGET '!H2:H13)} -> 18000000 | D19: 18000000 | E19: 18000000 | F19: 18000000 | G19: 19000000 | H19: 19000000 | I19: 20000000 | J19: 20000000 | K19: 20000000 | L19: 21000000 | M19: 21000000 | N19: 22000000
B20: Total Operating Expenses | C20: =SUM(C16:C19) -> 63000000 | D20: =SUM(D16:D19) -> 63000000 | E20: =SUM(E16:E19) -> 66000000 | F20: =SUM(F16:F19) -> 67000000 | G20: =SUM(G16:G19) -> 71000000 | H20: =SUM(H16:H19) -> 74000000 | I20: =SUM(I16:I19) -> 76000000 | J20: =SUM(J16:J19) -> 77000000 | ... N20: =SUM(N16:N19) -> 89000000
B22: Operating Income | C22: =C12-C20 -> -13692000 | D22: =D12-D20 -> -7416360 | E22: =E12-E20 -> -3522118.8 | F22: =F12-F20 -> 3046039.2 | G22: =G12-G20 -> 7348146.2 | H22: =H12-H20 -> 13449343 | I22: =I12-I20 -> 21420303 | J22: =J12-J20 -> 31337690 | ... N22: =N12-N20 -> 74243438
B23: Taxes | C23: =IF(C22*$C$24>0, C22*$C$24, 0) -> 0 | D23: =IF(D22*$C$24>0, D22*$C$24, 0) -> 0 | E23: =IF(E22*$C$24>0, E22*$C$24, 0) -> 0 | F23: =IF(F22*$C$24>0, F22*$C$24, 0) -> 456905.88 | G23: =IF(G22*$C$24>0, G22*$C$24, 0) -> 1102221.9 | H23: =IF(H22*$C$24>0, H22*$C$24, 0) -> 2017401.4 | I23: =IF(I22*$C$24>0, I22*$C$24, 0) -> 3213045.4 | J23: =IF(J22*$C$24>0, J22*$C$24, 0) -> 4700653.5 | ... N23: =IF(N22*$C$24>0, N22*$C$24, 0) -> 11136516
B24: Tax Rate | C24: 0.15
B27: Net Income | C27: =(C12-C23) -> 49308000 | D27: =(D12-D23) -> 55583640 | E27: =(E12-E23) -> 62477881 | F27: =(F12-F23) -> 69589133 | G27: =(G12-G23) -> 77245924 | H27: =(H12-H23) -> 85431942 | I27: =(I12-I23) -> 94207257 | J27: =(J12-J23) -> 1.0363704e+08 | ... N27: =(N12-N23) -> 1.5210692e+08

Sheet COST_VARIANCE ANALYSIS
A3: Variance Analysis | B3: 45839 | C3: 45870 | D3: 45901 | E3: 45931 | F3: 45962 | G3: 45992
A4: Revenue Variance | B4: ='ACTUAL RESULTS (JUL–DEC)'!D2-'ORIGINAL ANNUAL BUDGET '!D2 -> -13600000 | C4: ='ACTUAL RESULTS (JUL–DEC)'!D3-'ORIGINAL ANNUAL BUDGET '!D3 -> -13800000 | D4: ='ACTUAL RESULTS (JUL–DEC)'!D4-'ORIGINAL ANNUAL BUDGET '!D4 -> -17000000 | E4: ='ACTUAL RESULTS (JUL–DEC)'!D5-'ORIGINAL ANNUAL BUDGET '!D5 -> -17100000 | F4: ='ACTUAL RESULTS (JUL–DEC)'!D6-'ORIGINAL ANNUAL BUDGET '!D6 -> -22200000 | G4: ='ACTUAL RESULTS (JUL–DEC)'!D7-'ORIGINAL ANNUAL BUDGET '!D7 -> -22400000
A5: Price Variance | B5: =B4*'ACTUAL RESULTS (JUL–DEC)'!B2 -> -24480000000000 | C5: =C4*'ACTUAL RESULTS (JUL–DEC)'!B3 -> -26220000000000 | D5: =D4*'ACTUAL RESULTS (JUL–DEC)'!B4 -> -34000000000000 | E5: =E4*'ACTUAL RESULTS (JUL–DEC)'!B5 -> -35910000000000 | F5: =F4*'ACTUAL RESULTS (JUL–DEC)'!B6 -> -48840000000000 | G5: =G4*'ACTUAL RESULTS (JUL–DEC)'!B7 -> -53760000000000
A6: Total Revenue Variance | B6: =B4*'ORIGINAL ANNUAL BUDGET '!C2 -> -680000000 | C6: =C4*'ORIGINAL ANNUAL BUDGET '!C3 -> -690000000 | D6: =D4*'ORIGINAL ANNUAL BUDGET '!C4 -> -850000000 | E6: =E4*'ORIGINAL ANNUAL BUDGET '!C5 -> -855000000 | F6: =F4*'ORIGINAL ANNUAL BUDGET '!C6 -> -1110000000 | G6: =G4*'ORIGINAL ANNUAL BUDGET '!C7 -> -1120000000
